Workbook

Sheet visitsform
A1: Позначка часу | B1: Дата | C1: Занятие | D1: Статус | E1: Комментарий | F1: Кто
A3: 46015.719 | B3: 45988 | C3: Гимнастика | D3: проведено | F3: Демид
A4: 46015.72 | B4: 45988 | C4: Логопед | D4: проведено | F4: Демид
A5: 46015.72 | B5: 45990 | C5: Гимнастика | D5: проведено | F5: Демид
A6: 46015.72 | B6: 45993 | C6: Логопед | D6: проведено | F6: Демид
A7: 46015.72 | B7: 45993 | C7: Гимнастика | D7: проведено | F7: Демид
A8: 46015.721 | B8: 45995 | C8: Логопед | D8: проведено | F8: Демид
A9: 46015.721 | B9: 45995 | C9: Гимнастика | D9: проведено | F9: Демид
A10: 46015.721 | B10: 45997 | C10: Гимнастика | D10: проведено | F10: Демид
A11: 46015.721 | B11: 46000 | C11: Логопед | D11: проведено | F11: Демид
A12: 46015.722 | B12: 46000 | C12: Гимнастика | D12: проведено | F12: Демид
A13: 46015.724 | B13: 46002 | C13: Логопед | D13: проведено | F13: Демид
A14: 46015.724 | B14: 46002 | C14: Гимнастика | D14: проведено | F14: Демид
A15: 46015.724 | B15: 46004 | C15: Гимнастика | D15: перенесено | E15: подарочное занятие | F15: Демид
A16: 46015.725 | B16: 46007 | C16: Логопед | D16: проведено | F16: Демид
A17: 46015.725 | B17: 46007 | C17: Гимнастика | D17: проведено | F17: Демид
A18: 46015.725 | B18: 46009 | C18: Логопед | D18: проведено | F18: Демид
A19: 46015.725 | B19: 46009 | C19: Гимнастика | D19: проведено | F19: Демид
A20: 46015.726 | B20: 46011 | C20: Гимнастика | D20: пропущено | E20: был у бабули | F20: Демид
A21: 46015.726 | B21: 46014 | C21: Логопед | D21: проведено | F21: Демид
A22: 46015.726 | B22: 46014 | C22: Тренажор | D22: проведено | F22: Егор
A23: 46015.726 | B23: 46014 | C23: Гимнастика | D23: проведено | F23: Демид
A24: 46015.733 | B24: 46007 | C24: Тренажор | D24: проведено | F24: Егор
A25: 46015.734 | B25: 46002 | C25: Тренажор | D25: проведено | F25: Егор
A26: 46015.734 | B26: 46000 | C26: Тренажор | D26: проведено | F26: Егор
A27: 46015.734 | B27: 45995 | C27: Тренажор | D27: проведено | F27: Егор
A28: 46015.735 | B28: 45988 | C28: Тренажор | D28: проведено | F28: Егор
A29: 46015.738 | B29: 45994 | C29: Психолог | D29: проведено | F29: Егор
A30: 46015.738 | B30: 46001 | C30: Психолог | D30: проведено | F30: Егор
A31: 46015.738 | B31: 46008 | C31: Психолог | D31: проведено | F31: Егор
A32: 46015.741 | B32: 45992 | C32: Английский | D32: проведено | F32: Егор
... A38: 46015.742 | B38: 46013 | C38: Английский | D38: проведено | F38: Егор
A39: 46016.567 | B39: 46016 | C39: Логопед | D39: перенесено | E39: перенесла на пятницу | F39: Демид
A40: 46016.731 | B40: 46016 | C40: Тренажор | D40: проведено | F40: Егор
A41: 46016.731 | B41: 46016 | C41: Гимнастика | D41: проведено | F41: Демид
A42: 46017.489 | B42: 46017 | C42: Логопед | D42: проведено | F42: Демид
A43: 46018.755 | B43: 46018 | C43: Гимнастика | D43: проведено | F43: Демид
A44: 46018.97 | B44: 46017 | C44: Психолог | D44: проведено | F44: Егор
A45: 46021.587 | B45: 46021 | C45: Логопед | D45: проведено | F45: Демид
A46: 46021.788 | B46: 46021 | C46: Тренажор | D46: проведено | F46: Егор
...

Sheet current
A1: Кто | B1: Занятие | C1: Оплачено | D1: Прошло | E1: Осталось | F1: Цена/занятие | G1: Когда оплата
A2: Демид | B2: Гимнастика | C2: =sumifs(payments!D:D, payments!B:B, A2, payments!C:C, B2) -> 72 | D2: =COUNTIFS(visitsform!C:C, B2, visitsform!D:D, "проведено", visitsform!F:F, A2) -> 68 | E2: =C2-D2 -> 4 | F2: 150
A3: Демид | B3: Логопед | C3: =sumifs(payments!D:D, payments!B:B, A3, payments!C:C, B3) -> 48 | D3: =COUNTIFS(visitsform!C:C, B3, visitsform!D:D, "проведено", visitsform!F:F, A3) -> 47 | E3: =C3-D3 -> 1 | F3: 350
A4: Егор | B4: Тренажор | C4: =sumifs(payments!D:D, payments!B:B, A4, payments!C:C, B4) -> 20 | D4: =COUNTIFS(visitsform!C:C, B4, visitsform!D:D, "проведено", visitsform!F:F, A4) -> 20 | E4: =C4-D4 -> 0 | F4: 550
A5: Егор | B5: Психолог | C5: =sumifs(payments!D:D, payments!B:B, A5, payments!C:C, B5) -> 12 | D5: =COUNTIFS(visitsform!C:C, B5, visitsform!D:D, "проведено", visitsform!F:F, A5) -> 12 | E5: =C5-D5 -> 0 | F5: 1400
A6: Егор | B6: Английский | C6: =sumifs(payments!D:D, payments!B:B, A6, payments!C:C, B6) -> 47 | D6: =COUNTIFS(visitsform!C:C, B6, visitsform!D:D, "проведено", visitsform!F:F, A6) -> 47 | E6: =C6-D6 -> 0 | F6: 400
C7: =sumifs(payments!D:D, payments!B:B, A7, payments!C:C, B7) -> 0 | D7: =COUNTIFS(visitsform!C:C, B7, visitsform!D:D, "проведено", visitsform!F:F, A7) -> 0 | E7: =C7-D7 -> 0
C8: =sumifs(payments!D:D, payments!B:B, A8, payments!C:C, B8) -> 0 | D8: =COUNTIFS(visitsform!C:C, B8, visitsform!D:D, "проведено", visitsform!F:F, A8) -> 0 | E8: =C8-D8 -> 0
C9: =sumifs(payments!D:D, payments!B:B, A9, payments!C:C, B9) -> 0 | D9: =COUNTIFS(visitsform!C:C, B9, visitsform!D:D, "проведено", visitsform!F:F, A9) -> 0 | E9: =C9-D9 -> 0
C10: =sumifs(payments!D:D, payments!B:B, A10, payments!C:C, B10) -> 0 | D10: =COUNTIFS(visitsform!C:C, B10, visitsform!D:D, "проведено", visitsform!F:F, A10) -> 0 | E10: =C10-D10 -> 0
C11: =sumifs(payments!D:D, payments!B:B, A11, payments!C:C, B11) -> 0 | D11: =COUNTIFS(visitsform!C:C, B11, visitsform!D:D, "проведено", visitsform!F:F, A11) -> 0 | E11: =C11-D11 -> 0
C12: =sumifs(payments!D:D, payments!B:B, A12, payments!C:C, B12) -> 0 | D12: =COUNTIFS(visitsform!C:C, B12, visitsform!D:D, "проведено", visitsform!F:F, A12) -> 0 | E12: =C12-D12 -> 0
C13: =sumifs(payments!D:D, payments!B:B, A13, payments!C:C, B13) -> 0 | D13: =COUNTIFS(visitsform!C:C, B13, visitsform!D:D, "проведено", visitsform!F:F, A13) -> 0 | E13: =C13-D13 -> 0
C14: =sumifs(payments!D:D, payments!B:B, A14, payments!C:C, B14) -> 0 | D14: =COUNTIFS(visitsform!C:C, B14, visitsform!D:D, "проведено", visitsform!F:F, A14) -> 0 | E14: =C14-D14 -> 0
C15: =sumifs(payments!D:D, payments!B:B, A15, payments!C:C, B15) -> 0 | D15: =COUNTIFS(visitsform!C:C, B15, visitsform!D:D, "проведено", visitsform!F:F, A15) -> 0 | E15: =C15-D15 -> 0

Sheet payments
A1: Дата | B1: Кто | C1: Занятие | D1: Количество занятий | E1: Сумма | F1: Комментарий | H1: Сумма
A2: 45988 | B2: Демид | C2: Логопед | D2: 3 | E2: 900 | H2: =sum(E:E) -> 72000
A3: 45988 | B3: Демид | C3: Гимнастика | D3: 16 | E3: 2400
A4: 46000 | B4: Демид | C4: Логопед | D4: 4 | E4: 1200
A5: 46014 | B5: Демид | C5: Логопед | D5: 4 | E5: 1200
A6: 46014 | B6: Егор | C6: Тренажор | D6: 1 | E6: 550
A7: 46007 | B7: Егор | C7: Тренажор | D7: 1 | E7: 550
A8: 46002 | B8: Егор | C8: Тренажор | D8: 2 | E8: 1100
A9: 45995 | B9: Егор | C9: Тренажор | D9: 1 | E9: 550
A10: 45988 | B10: Егор | C10: Тренажор | D10: 1 | E10: 550
A11: 45992 | B11: Егор | C11: Психолог | D11: 3 | E11: 4200
A12: 45992 | B12: Егор | C12: Английский | D12: 9 | E12: 3600
A13: 46016 | B13: Егор | C13: Психолог | D13: 1 | E13: 1400
A14: 46016 | B14: Егор | C14: Тренажор | D14: 1 | E14: 550
... A54: 46151 | B54: Демид | C54: Гимнастика | D54: 8 | E54: 1200

Sheet lists
A1: Гимнастика | B1: Егор | C1: проведено
A2: Логопед | B2: Демид | C2: перенесено
A3: Тренажор | C3: отменено
A4: Психолог | C4: пропущено
A5: Английский
